Workbook

Sheet 00 Instruções
A1: Validação do catálogo de opções do Pedido
A3: Como preencher | D3: Abrir resumo
A4: 1. Abra cada aba de categoria.
A5: 2. Escolha uma decisão no menu da coluna A para cada opção.
A6: 3. Se escolher Renomear, escreva o nome correto na coluna D.
A7: 4. Use as linhas roxas no fim da aba para adicionar opções ausentes.
A8: 5. Não preencher preços nesta etapa.
A10: Decisão | B10: Significado
A11: Manter | B11: A Silmer usa/vende esta opção com este nome.
A12: Remover | B12: A opção não faz parte do catálogo.
A13: Renomear | B13: A opção existe, mas o nome correto deve ser informado.
A14: Confirmar depois | B14: A decisão depende de nova conferência.
A15: Adicionar | B15: Nova opção que não estava na lista inicial.
A18: Controle da revisão
A19: Status geral | B19: Não iniciado
A20: Revisado por
A21: Data
A22: Pendências restantes
A23: Versão aprovada

Sheet Resumo
A1: Resumo das decisões por categoria
A3: Categoria | B3: Opções iniciais | C3: Manter | D3: Remover | E3: Renomear | F3: Confirmar depois | G3: Novas opções
A4: Tipos de peça ou produto | B4: 26 | C4: =COUNTIF('01 Tipos de peça'!A:A,"Manter") | D4: =COUNTIF('01 Tipos de peça'!A:A,"Remover") | E4: =COUNTIF('01 Tipos de peça'!A:A,"Renomear") | F4: =COUNTIF('01 Tipos de peça'!A:A,"Confirmar depois") | G4: =COUNTIFS('01 Tipos de peça'!A:A,"Adicionar",'01 Tipos de peça'!C:C,"<>")
A5: Modelagem e caimento | B5: 9 | C5: =COUNTIF('02 Modelagem'!A:A,"Manter") | D5: =COUNTIF('02 Modelagem'!A:A,"Remover") | E5: =COUNTIF('02 Modelagem'!A:A,"Renomear") | F5: =COUNTIF('02 Modelagem'!A:A,"Confirmar depois") | G5: =COUNTIFS('02 Modelagem'!A:A,"Adicionar",'02 Modelagem'!C:C,"<>")
A6: Golas e decotes | B6: 11 | C6: =COUNTIF('03 Golas e decotes'!A:A,"Manter") | D6: =COUNTIF('03 Golas e decotes'!A:A,"Remover") | E6: =COUNTIF('03 Golas e decotes'!A:A,"Renomear") | F6: =COUNTIF('03 Golas e decotes'!A:A,"Confirmar depois") | G6: =COUNTIFS('03 Golas e decotes'!A:A,"Adicionar",'03 Golas e decotes'!C:C,"<>")
A7: Mangas | B7: 10 | C7: =COUNTIF('04 Mangas'!A:A,"Manter") | D7: =COUNTIF('04 Mangas'!A:A,"Remover") | E7: =COUNTIF('04 Mangas'!A:A,"Renomear") | F7: =COUNTIF('04 Mangas'!A:A,"Confirmar depois") | G7: =COUNTIFS('04 Mangas'!A:A,"Adicionar",'04 Mangas'!C:C,"<>")
A8: Malhas e tecidos | B8: 56 | C8: =COUNTIF('05 Malhas e tecidos'!A:A,"Manter") | D8: =COUNTIF('05 Malhas e tecidos'!A:A,"Remover") | E8: =COUNTIF('05 Malhas e tecidos'!A:A,"Renomear") | F8: =COUNTIF('05 Malhas e tecidos'!A:A,"Confirmar depois") | G8: =COUNTIFS('05 Malhas e tecidos'!A:A,"Adicionar",'05 Malhas e tecidos'!C:C,"<>")
A9: Cores | B9: 37 | C9: =COUNTIF('06 Cores'!A:A,"Manter") | D9: =COUNTIF('06 Cores'!A:A,"Remover") | E9: =COUNTIF('06 Cores'!A:A,"Renomear") | F9: =COUNTIF('06 Cores'!A:A,"Confirmar depois") | G9: =COUNTIFS('06 Cores'!A:A,"Adicionar",'06 Cores'!C:C,"<>")
A10: Acabamentos de gola, manga e barra | B10: 17 | C10: =COUNTIF('07 Acabamentos'!A:A,"Manter") | D10: =COUNTIF('07 Acabamentos'!A:A,"Remover") | E10: =COUNTIF('07 Acabamentos'!A:A,"Renomear") | F10: =COUNTIF('07 Acabamentos'!A:A,"Confirmar depois") | G10: =COUNTIFS('07 Acabamentos'!A:A,"Adicionar",'07 Acabamentos'!C:C,"<>")
A11: Construção e adicionais da peça | B11: 33 | C11: =COUNTIF('08 Construção'!A:A,"Manter") | D11: =COUNTIF('08 Construção'!A:A,"Remover") | E11: =COUNTIF('08 Construção'!A:A,"Renomear") | F11: =COUNTIF('08 Construção'!A:A,"Confirmar depois") | G11: =COUNTIFS('08 Construção'!A:A,"Adicionar",'08 Construção'!C:C,"<>")
A12: Tamanhos e grades | B12: 49 | C12: =COUNTIF('09 Tamanhos e grades'!A:A,"Manter") | D12: =COUNTIF('09 Tamanhos e grades'!A:A,"Remover") | E12: =COUNTIF('09 Tamanhos e grades'!A:A,"Renomear") | F12: =COUNTIF('09 Tamanhos e grades'!A:A,"Confirmar depois") | G12: =COUNTIFS('09 Tamanhos e grades'!A:A,"Adicionar",'09 Tamanhos e grades'!C:C,"<>")
A13: Tipos de estampa e personalização | B13: 17 | C13: =COUNTIF('10 Estampas'!A:A,"Manter") | D13: =COUNTIF('10 Estampas'!A:A,"Remover") | E13: =COUNTIF('10 Estampas'!A:A,"Renomear") | F13: =COUNTIF('10 Estampas'!A:A,"Confirmar depois") | G13: =COUNTIFS('10 Estampas'!A:A,"Adicionar",'10 Estampas'!C:C,"<>")
A14: Locais da estampa ou personalização | B14: 30 | C14: =COUNTIF('11 Locais aplicação'!A:A,"Manter") | D14: =COUNTIF('11 Locais aplicação'!A:A,"Remover") | E14: =COUNTIF('11 Locais aplicação'!A:A,"Renomear") | F14: =COUNTIF('11 Locais aplicação'!A:A,"Confirmar depois") | G14: =COUNTIFS('11 Locais aplicação'!A:A,"Adicionar",'11 Locais aplicação'!C:C,"<>")
A15: Situação e serviço de arte | B15: 8 | C15: =COUNTIF('12 Arte'!A:A,"Manter") | D15: =COUNTIF('12 Arte'!A:A,"Remover") | E15: =COUNTIF('12 Arte'!A:A,"Renomear") | F15: =COUNTIF('12 Arte'!A:A,"Confirmar depois") | G15: =COUNTIFS('12 Arte'!A:A,"Adicionar",'12 Arte'!C:C,"<>")
A16: Finalidade do pedido | B16: 10 | C16: =COUNTIF('13 Finalidade'!A:A,"Manter") | D16: =COUNTIF('13 Finalidade'!A:A,"Remover") | E16: =COUNTIF('13 Finalidade'!A:A,"Renomear") | F16: =COUNTIF('13 Finalidade'!A:A,"Confirmar depois") | G16: =COUNTIFS('13 Finalidade'!A:A,"Adicionar",'13 Finalidade'!C:C,"<>")
A17: Perfil de compra | B17: 5 | C17: =COUNTIF('14 Perfil compra'!A:A,"Manter") | D17: =COUNTIF('14 Perfil compra'!A:A,"Remover") | E17: =COUNTIF('14 Perfil compra'!A:A,"Renomear") | F17: =COUNTIF('14 Perfil compra'!A:A,"Confirmar depois") | G17: =COUNTIFS('14 Perfil compra'!A:A,"Adicionar",'14 Perfil compra'!C:C,"<>")
A18: Modalidade de entrega | B18: 5 | C18: =COUNTIF('15 Entrega'!A:A,"Manter") | D18: =COUNTIF('15 Entrega'!A:A,"Remover") | E18: =COUNTIF('15 Entrega'!A:A,"Renomear") | F18: =COUNTIF('15 Entrega'!A:A,"Confirmar depois") | G18: =COUNTIFS('15 Entrega'!A:A,"Adicionar",'15 Entrega'!C:C,"<>")

Sheet 01 Tipos de peça
A1: Tipos de peça ou produto
A2: Selecione uma decisão na coluna A. Em Renomear, informe o nome correto na coluna D.
A3: Decisão | B3: Grupo/subcategoria | C3: Opção | D3: Nome correto / observação
B4: Vestuário superior | C4: Camiseta
B5: Vestuário superior | C5: Camisa casual | D5: Confirmar se é diferente de camiseta.
B6: Vestuário superior | C6: Camisa polo
B7: Vestuário superior | C7: Camisa esportiva
B8: Vestuário superior | C8: Regata tradicional
B9: Vestuário superior | C9: Regata machão
B10: Vestuário superior | C10: Abadá | D10: Confirmar se é tipo próprio ou variação de regata/camiseta.
B11: Vestuário superior | C11: Baby look | D11: Confirmar se é produto ou modelagem.
B12: Vestuário superior | C12: Cropped | D12: Confirmar se é produto ou modelagem.
B13: Vestuário superior | C13: Camiseta de manga longa | D13: Confirmar se é produto ou variação de camiseta.
B14: Frio | C14: Moletom sem capuz
B15: Frio | C15: Moletom com capuz
B16: Frio | C16: Moletom canguru
B17: Frio | C17: Jaqueta/agasalho
B18: Profissional | C18: Colete
B19: Profissional | C19: Jaleco
B20: Profissional | C20: Avental
B21: Vestuário inferior | C21: Short
B22: Vestuário inferior | C22: Bermuda
B23: Vestuário inferior | C23: Calça
B24: Vestuário inferior | C24: Saia
B25: Vestuário inferior | C25: Short-saia
B26: Acessório | C26: Boné | D26: Exige campos próprios.
B27: Acessório | C27: Viseira | D27: Exige campos próprios.
B28: Acessório | C28: Ecobag/sacola | D28: Exige campos próprios.
B29: Agrupamento | C29: Kit/conjunto de duas peças | D29: Confirmar se é produto ou agrupamento de itens.
A31: ADICIONAR OPÇÕES QUE ESTÃO FALTANDO
A32: Adicionar
A33: Adicionar
A34: Adicionar
A35: Adicionar
A36: Adicionar
A37: Adicionar
A38: Adicionar
A39: Adicionar
A40: Adicionar
A41: Adicionar

Sheet 02 Modelagem
A1: Modelagem e caimento
A2: Selecione uma decisão na coluna A. Em Renomear, informe o nome correto na coluna D.
A3: Decisão | B3: Grupo/subcategoria | C3: Opção | D3: Nome correto / observação
B4: Modelagem | C4: Tradicional/unissex
B5: Modelagem | C5: Masculina reta
B6: Modelagem | C6: Feminina acinturada/baby look
B7: Modelagem | C7: Slim
B8: Modelagem | C8: Oversized
B9: Modelagem | C9: Infantil
B10: Modelagem | C10: Plus size
B11: Modelagem | C11: Esportiva
B12: Modelagem | C12: Personalizada/sob medida | D12: Exige análise humana.
A14: ADICIONAR OPÇÕES QUE ESTÃO FALTANDO
A15: Adicionar
A16: Adicionar
A17: Adicionar
A18: Adicionar
A19: Adicionar
A20: Adicionar
A21: Adicionar
A22: Adicionar
A23: Adicionar
A24: Adicionar

Sheet 03 Golas e decotes
A1: Golas e decotes
A2: Selecione uma decisão na coluna A. Em Renomear, informe o nome correto na coluna D.
A3: Decisão | B3: Grupo/subcategoria | C3: Opção | D3: Nome correto / observação
B4: Gola/decote | C4: Careca/redonda
B5: Gola/decote | C5: Gola V
B6: Gola/decote | C6: Gola polo
B7: Gola/decote | C7: Gola padre
B8: Gola/decote | C8: Gola canoa
B9: Gola/decote | C9: Gola alta
B10: Gola/decote | C10: Gola olímpica | D10: Confirmar o significado usado pela Silmer.
B11: Gola/decote | C11: Decote ombro a ombro
B12: Gola/decote | C12: Capuz
B13: Gola/decote | C13: Sem gola/não se aplica
B14: Gola/decote | C14: Personalizada | D14: Exige análise humana.
A16: ADICIONAR OPÇÕES QUE ESTÃO FALTANDO
A17: Adicionar
A18: Adicionar
A19: Adicionar
A20: Adicionar
A21: Adicionar
A22: Adicionar
A23: Adicionar
A24: Adicionar
A25: Adicionar
A26: Adicionar

Sheet 04 Mangas
A1: Mangas
A2: Selecione uma decisão na coluna A. Em Renomear, informe o nome correto na coluna D.
A3: Decisão | B3: Grupo/subcategoria | C3: Opção | D3: Nome correto / observação
B4: Manga | C4: Sem manga
B5: Manga | C5: Curta
B6: Manga | C6: 3/4
B7: Manga | C7: Longa
B8: Manga | C8: Raglan curta
B9: Manga | C9: Raglan longa
B10: Manga | C10: Japonesa
B11: Manga | C11: Morcego
B12: Manga | C12: Com punho
B13: Manga | C13: Personalizada | D13: Exige análise humana.
A15: ADICIONAR OPÇÕES QUE ESTÃO FALTANDO
A16: Adicionar
A17: Adicionar
A18: Adicionar
A19: Adicionar
A20: Adicionar
A21: Adicionar
A22: Adicionar
A23: Adicionar
A24: Adicionar
A25: Adicionar

Sheet 05 Malhas e tecidos
A1: Malhas e tecidos
A2: Selecione uma decisão na coluna A. Em Renomear, informe o nome correto na coluna D.
A3: Decisão | B3: Grupo/subcategoria | C3: Opção | D3: Nome correto / observação
B4: Algodão e mistos leves | C4: Meia malha de algodão cardada
B5: Algodão e mistos leves | C5: Meia malha de algodão penteada 24.1
B6: Algodão e mistos leves | C6: Meia malha de algodão penteada 30.1
B7: Algodão e mistos leves | C7: Meia malha de algodão com elastano
B8: Algodão e mistos leves | C8: Cotton — algodão com elastano
B9: Algodão e mistos leves | C9: PV liso anti-pilling
B10: Algodão e mistos leves | C10: PV mescla anti-pilling
B11: Algodão e mistos leves | C11: PV com elastano
B12: Algodão e mistos leves | C12: PP/poliéster liso
B13: Algodão e mistos leves | C13: PP/poliéster dry
B14: Algodão e mistos leves | C14: PP/poliéster mescla
B15: Algodão e mistos leves | C15: Poliéster/algodão | D15: Informar a composição; não usar apenas PA.
B16: Piquet | C16: Piquet de algodão
B17: Piquet | C17: Piquet PV
B18: Piquet | C18: Piquet poliéster/algodão
B19: Piquet | C19: Piquet de poliéster
B20: Piquet | C20: Piquet com elastano
B21: Piquet | C21: Piquet anti-pilling
B22: Dry fit e esportivos | C22: Dry fit liso de poliéster
B23: Dry fit e esportivos | C23: Dry fit ponto de arroz/favinho
B24: Dry fit e esportivos | C24: Dry fit colmeia
B25: Dry fit e esportivos | C25: Dry fit furadinho
B26: Dry fit e esportivos | C26: Dry fit light
B27: Dry fit e esportivos | C27: Dry fit mescla
... B32: Dry fit e esportivos | C32: Helanca dry
B33: Dry fit e esportivos | C33: Helanquinha | D33: Nome usado na ficha; confirmar composição/equivalência.
B34: Dry fit e esportivos | C34: Light | D34: Nome isolado usado na ficha; confirmar significado.
B35: Outros tecidos | C35: Cacharrel
B36: Outros tecidos | C36: Interlock de algodão
B37: Outros tecidos | C37: Interlock de poliéster
B38: Outros tecidos | C38: Interlock misto
B39: Outros tecidos | C39: Liganete
B40: Outros tecidos | C40: Viscolycra
B41: Outros tecidos | C41: Suplex de poliamida com elastano
B42: Outros tecidos | C42: Suplex de poliéster com elastano
B43: Outros tecidos | C43: Microfibra
B44: Outros tecidos | C44: Tactel
...

Sheet 06 Cores
A1: Cores
A2: Selecione uma decisão na coluna A. Em Renomear, informe o nome correto na coluna D.
A3: Decisão | B3: Grupo/subcategoria | C3: Opção | D3: Nome correto / observação
B4: Neutros | C4: Branco
B5: Neutros | C5: Off-white/natural
B6: Neutros | C6: Preto
B7: Neutros | C7: Cinza claro
B8: Neutros | C8: Cinza mescla
B9: Neutros | C9: Grafite/chumbo
B10: Azuis | C10: Azul-marinho
B11: Azuis | C11: Azul royal
B12: Azuis | C12: Azul-celeste
B13: Azuis | C13: Azul-turquesa
B14: Azuis | C14: Azul-petróleo
B15: Verdes | C15: Verde-bandeira
... B39: Especiais | C39: Estampado
B40: Personalizada | C40: Código Pantone ou referência visual | D40: Validar no material e cartela do fornecedor.
A42: ADICIONAR OPÇÕES QUE ESTÃO FALTANDO
A43: Adicionar
A44: Adicionar
A45: Adicionar
A46: Adicionar
A47: Adicionar
A48: Adicionar
A49: Adicionar
A50: Adicionar
A51: Adicionar
A52: Adicionar

Sheet 07 Acabamentos
A1: Acabamentos de gola, manga e barra
A2: Selecione uma decisão na coluna A. Em Renomear, informe o nome correto na coluna D.
A3: Decisão | B3: Grupo/subcategoria | C3: Opção | D3: Nome correto / observação
B4: Tipo | C4: Próprio tecido
B5: Tipo | C5: Viés do próprio tecido
B6: Tipo | C6: Viés contrastante
B7: Tipo | C7: Ribana
B8: Tipo | C8: Gola pronta
B9: Tipo | C9: Punho pronto
B10: Tipo | C10: Galão
B11: Tipo | C11: Bainha simples
B12: Tipo | C12: Galoneira
B13: Tipo | C13: Elástico
B14: Tipo | C14: Sem acabamento separado
B15: Perfil | C15: Liso
... B20: Perfil | C20: Personalizado
A22: ADICIONAR OPÇÕES QUE ESTÃO FALTANDO
A23: Adicionar
A24: Adicionar
A25: Adicionar
A26: Adicionar
A27: Adicionar
A28: Adicionar
A29: Adicionar
A30: Adicionar
A31: Adicionar
A32: Adicionar

Sheet 08 Construção
A1: Construção e adicionais da peça
A2: Selecione uma decisão na coluna A. Em Renomear, informe o nome correto na coluna D.
A3: Decisão | B3: Grupo/subcategoria | C3: Opção | D3: Nome correto / observação
B4: Abertura | C4: Sem abertura
B5: Abertura | C5: Botões
B6: Abertura | C6: Zíper parcial
B7: Abertura | C7: Zíper total
B8: Bolso | C8: Sem bolso
B9: Bolso | C9: Peito
B10: Bolso | C10: Frontal
B11: Bolso | C11: Canguru
B12: Bolso | C12: Lateral
B13: Bolso | C13: Personalizado
B14: Recortes | C14: Sem recorte
B15: Recortes | C15: Lateral
... B36: Complemento | C36: Outro
A38: ADICIONAR OPÇÕES QUE ESTÃO FALTANDO
A39: Adicionar
A40: Adicionar
A41: Adicionar
A42: Adicionar
A43: Adicionar
A44: Adicionar
A45: Adicionar
A46: Adicionar
A47: Adicionar
A48: Adicionar

Sheet 09 Tamanhos e grades
A1: Tamanhos e grades
A2: Selecione uma decisão na coluna A. Em Renomear, informe o nome correto na coluna D.
A3: Decisão | B3: Grupo/subcategoria | C3: Opção | D3: Nome correto / observação
B4: Bebê | C4: RN
B5: Bebê | C5: P
B6: Bebê | C6: M
B7: Bebê | C7: G
B8: Bebê | C8: GG
B9: Bebê por meses | C9: 0–3 meses
B10: Bebê por meses | C10: 3–6 meses
B11: Bebê por meses | C11: 6–9 meses
B12: Bebê por meses | C12: 9–12 meses
B13: Bebê por meses | C13: 12–18 meses
B14: Bebê por meses | C14: 18–24 meses
B15: Infantil | C15: 2
... B27: Adulto alfabético | C27: GG
B28: Adulto alfabético | C28: XG | D28: Confirmar equivalência com G1.
B29: Adulto alfabético | C29: XGG | D29: Confirmar equivalência com G2.
B30: Plus size | C30: G1
B31: Plus size | C31: G2
B32: Plus size | C32: G3
B33: Plus size | C33: G4
B34: Plus size | C34: G5
B35: Numérico | C35: 34
B36: Numérico | C36: 36
B37: Numérico | C37: 38
B38: Numérico | C38: 40
B39: Numérico | C39: 42
B40: Numérico | C40: 44
B41: Numérico | C41: 46
... B49: Especial | C49: Tamanho único
B50: Especial | C50: Sob medida/com medidas informadas | D50: Exige análise humana.
B51: Termo da ficha | C51: XX | D51: Confirmar significado e equivalência.
B52: Termo da ficha | C52: JEGÃO | D52: Confirmar significado e equivalência.
A54: ADICIONAR OPÇÕES QUE ESTÃO FALTANDO
A55: Adicionar
A56: Adicionar
A57: Adicionar
A58: Adicionar
A59: Adicionar
...

Sheet 10 Estampas
A1: Tipos de estampa e personalização
A2: Selecione uma decisão na coluna A. Em Renomear, informe o nome correto na coluna D.
A3: Decisão | B3: Grupo/subcategoria | C3: Opção | D3: Nome correto / observação
B4: Aplicação | C4: Sem aplicação
B5: Sublimação | C5: Sublimação total/full print
B6: Sublimação | C6: Sublimação localizada
B7: Impressão | C7: Serigrafia/silk screen
B8: Impressão | C8: DTF — direto no filme
B9: Impressão | C9: DTG/silk digital — direto na peça
B10: Transfer | C10: Transfer sublimático
B11: Transfer | C11: Transfer serigráfico/plastisol
B12: Transfer | C12: Vinil termotransferível/HTV
B13: Bordado/aplique | C13: Bordado direto
B14: Bordado/aplique | C14: Patch/bordado aplicado
B15: Bordado/aplique | C15: Aplique costurado
... B20: Efeito especial | C20: Puff/alto-relevo
A22: ADICIONAR OPÇÕES QUE ESTÃO FALTANDO
A23: Adicionar
A24: Adicionar
A25: Adicionar
A26: Adicionar
A27: Adicionar
A28: Adicionar
A29: Adicionar
A30: Adicionar
A31: Adicionar
A32: Adicionar

Sheet 11 Locais aplicação
A1: Locais da estampa ou personalização
A2: Selecione uma decisão na coluna A. Em Renomear, informe o nome correto na coluna D.
A3: Decisão | B3: Grupo/subcategoria | C3: Opção | D3: Nome correto / observação
B4: Frente | C4: Total
B5: Frente | C5: Centro
B6: Frente | C6: Peito esquerdo
B7: Frente | C7: Peito direito
B8: Frente | C8: Barra
B9: Frente | C9: Bolso
B10: Costas | C10: Total
B11: Costas | C11: Superior
B12: Costas | C12: Centro
B13: Costas | C13: Inferior/barra
B14: Mangas | C14: Direita
B15: Mangas | C15: Esquerda
... B32: Boné/viseira | C32: Traseira
B33: Outro | C33: Local personalizado | D33: Descrever e aprovar manualmente.
A35: ADICIONAR OPÇÕES QUE ESTÃO FALTANDO
A36: Adicionar
A37: Adicionar
A38: Adicionar
A39: Adicionar
A40: Adicionar
A41: Adicionar
A42: Adicionar
A43: Adicionar
A44: Adicionar
A45: Adicionar

Sheet 12 Arte
A1: Situação e serviço de arte
A2: Selecione uma decisão na coluna A. Em Renomear, informe o nome correto na coluna D.
A3: Decisão | B3: Grupo/subcategoria | C3: Opção | D3: Nome correto / observação
B4: Situação da arte | C4: Arte pronta e aprovada
B5: Situação da arte | C5: Arte pronta, precisa de ajuste
B6: Situação da arte | C6: Cliente enviará a arte depois
B7: Serviço Silmer | C7: Vetorização/adaptação pela Silmer
B8: Serviço Silmer | C8: Criação pela Silmer
B9: Histórico | C9: Reutilizar arte de pedido anterior
B10: Não aplicável | C10: Sem arte/sem aplicação
B11: Pendência | C11: Pendente de análise humana
A13: ADICIONAR OPÇÕES QUE ESTÃO FALTANDO
A14: Adicionar
A15: Adicionar
A16: Adicionar
A17: Adicionar
A18: Adicionar
A19: Adicionar
A20: Adicionar
A21: Adicionar
A22: Adicionar
A23: Adicionar

Sheet 13 Finalidade
A1: Finalidade do pedido
A2: Selecione uma decisão na coluna A. Em Renomear, informe o nome correto na coluna D.
A3: Decisão | B3: Grupo/subcategoria | C3: Opção | D3: Nome correto / observação
B4: Finalidade | C4: Evento
B5: Finalidade | C5: Uniforme empresarial
B6: Finalidade | C6: Uniforme escolar
B7: Finalidade | C7: Equipe esportiva
B8: Finalidade | C8: Corrida
B9: Finalidade | C9: Bloco/abadá
B10: Finalidade | C10: Igreja/grupo
B11: Finalidade | C11: Campanha/promocional
B12: Finalidade | C12: Revenda
B13: Finalidade | C13: Uso próprio
A15: ADICIONAR OPÇÕES QUE ESTÃO FALTANDO
A16: Adicionar
A17: Adicionar
A18: Adicionar
A19: Adicionar
A20: Adicionar
A21: Adicionar
A22: Adicionar
A23: Adicionar
A24: Adicionar
A25: Adicionar

Sheet 14 Perfil compra
A1: Perfil de compra
A2: Selecione uma decisão na coluna A. Em Renomear, informe o nome correto na coluna D.
A3: Decisão | B3: Grupo/subcategoria | C3: Opção | D3: Nome correto / observação
B4: Perfil | C4: Pessoa para uso próprio
B5: Perfil | C5: Empresa/organização
B6: Perfil | C6: Organizador de evento
B7: Perfil | C7: Revenda/atacado
B8: Perfil | C8: Cliente recorrente
A10: ADICIONAR OPÇÕES QUE ESTÃO FALTANDO
A11: Adicionar
A12: Adicionar
A13: Adicionar
A14: Adicionar
A15: Adicionar
A16: Adicionar
A17: Adicionar
A18: Adicionar
A19: Adicionar
A20: Adicionar

Sheet 15 Entrega
A1: Modalidade de entrega
A2: Selecione uma decisão na coluna A. Em Renomear, informe o nome correto na coluna D.
A3: Decisão | B3: Grupo/subcategoria | C3: Opção | D3: Nome correto / observação
B4: Entrega | C4: Retirada na Silmer
B5: Entrega | C5: Entrega local
B6: Entrega | C6: Transportadora
B7: Entrega | C7: Correios/outro operador
B8: Entrega | C8: Entrega a combinar
A10: ADICIONAR OPÇÕES QUE ESTÃO FALTANDO
A11: Adicionar
A12: Adicionar
A13: Adicionar
A14: Adicionar
A15: Adicionar
A16: Adicionar
A17: Adicionar
A18: Adicionar
A19: Adicionar
A20: Adicionar
